Workbook

Sheet 投入カレンダー
B2: DROP_Timeline
B5: 年度 | C5: 2025 | W5: 2026
B6: シーズン | C6: 25FW | AD6: 26SS | AY6: 26FW
B7: 年月 | C7: 45870 | G7: 45901 | K7: 45931 | O7: 45962 | S7: 45992 | W7: 46023 | AA7: 46054 | AE7: 46082 | AI7: 46113 | AM7: 46143 | AQ7: 46174 | AU7: 46204 | AY7: 46235
B8: 区分 | C8: D1 | F8: D2 | I8: D3 | K8: D4 | AD8: D1 | AG8: D2 | AI8: D3 | AL8: D4 | AY8: D1
B9: 週（W） | C9: １W | D9: 2W | E9: 3W | F9: 4W | G9: １W | H9: 2W | I9: 3W | J9: 4W | K9: １W | L9: 2W | M9: 3W | N9: 4W | O9: １W | P9: 2W | Q9: 3W | R9: 4W | S9: １W | T9: 2W | U9: 3W | V9: 4W | W9: １W | X9: 2W | Y9: 3W | Z9: 4W | AA9: １W | AB9: 2W | AC9: 3W | AD9: 4W | AE9: １W | AF9: 2W | AG9: 3W | AH9: 4W | AI9: １W | AJ9: 2W | AK9: 3W | AL9: 4W | AM9: １W | AN9: 2W | AO9: 3W | AP9: 4W | AQ9: １W | AR9: 2W | AS9: 3W | AT9: 4W | AU9: １W | AV9: 2W | AW9: 3W | AX9: 4W | AY9: １W | AZ9: 2W | BA9: 3W | BB9: 4W
B10: 日付 | C10: 45870 | F10: 45894 | I10: 45915 | K10: 45936 | AD10: 46076 | AG10: 46097 | AI10: 46118 | AL10: 46139
B11: イベント/アクション | C11: デイリー定番企画 ・プレフォール、秋口の早出しでグッズ中心。酷暑から秋口まで使えそうなラインナップ。 コラボ企画 | F11: テック定番企画 コラボ企画 | I11: デイリー企画 コラボ企画 | K11: テック定番企画 ・肌寒くなる季節から春先まで長く快適に使える商品群 コラボ企画 ・どこかあればスポットで追加投入 | AD11: 定番企画 コラボ企画 | AG11: 定番企画 コラボ企画 | AI11: 定番企画 コラボ企画 | AL11: 定番企画 コラボ企画
B12: 対象商品/カテゴリ | C12: バッグ類 ・トートバッグ 小物類 ・キャップ類 アパレル類 ・Tシャツ ・長袖シャツ | F12: 羽織もの・セーター | I12: グッズ関係 | K12: 防寒小物 ・ネックウォーマー ・保温ソックス アクセ
B13: 担当者
B14: 備考 | C14: プレスリリース配信 SNSでティーザー投稿 SNS広告 LP作成 | F14: プレスリリース配信 SNSでティーザー投稿 SNS広告 LP作成 | I14: プレスリリース配信 SNSでティーザー投稿 SNS広告 LP作成 | K14: プレスリリース配信 SNSでティーザー投稿 SNS広告 LP作成 | AD14: プレスリリース配信 SNSでティーザー投稿 SNS広告 LP作成 | AG14: プレスリリース配信 SNSでティーザー投稿 SNS広告 LP作成 | AI14: プレスリリース配信 SNSでティーザー投稿 SNS広告 LP作成 | AL14: プレスリリース配信 SNSでティーザー投稿 SNS広告 LP作成
B16: Seasonal Action
B17: Sales・その他 | C17: プレフォール | I17: ハロウィーンコレクション | P17: 独身の日 | R17: ブラックフライデー | U17: クリスマスギフト商戦 | V17: 初売り・福袋 | AB17: バレンタイン | AF17: ホワイトデー | AH17: 春の新生活フェア | AL17: GWスペシャルSALE | AQ17: 梅雨対策・クールビズ | AU17: SUMMER SALE
B18: fashion | C18: 秋ファッション | K18: 冬ファッション | W18: 春ファッション | AI18: 夏ファッション | AU18: 秋ファッション
G19: 防寒アイテム | AI19: 日焼け・日差し | AM19: 梅雨 | AQ19: 暑さ対策
B20: sports
B21: Life event | C21: 夏休み | E21: 敬老の日 | G21: 月見 | I21: シルバーウィーク | N21: ハロウィーン | O21: 七五三 | Q21: 運動会 | U21: クリスマス | W21: お正月 | X21: 成人式 | AA21: 節分 | AB21: バレンタイン | AE21: ひな祭り | AF21: ホワイトデー | AG21: 卒業 | AI21: 入学・入園 | AJ21: イースター | AL21: GW | AM21: こどもの日 | AO21: 母の日 | AQ21: 父の日 | AU21: 七夕 | AY21: 夏休み | BA21: 敬老の日
B22: SALE | G22: 楽天スーパーセール | K22: AMAZONプライム感謝祭 | O22: 楽天ブラックフライデー | T22: 楽天スーパーセール | AE22: 楽天スーパーセール | AQ22: 楽天スーパーセール | AU22: AMAZONプライムデー
B23: leisure
B24: Fes | C24: Sziget Festival（ブダペスト 🇭🇺） | D24: Summer Sonic（東京・大阪 🇯🇵） | K24: Austin City Limits (ACL)（オースティン 🇺🇸） | S24: Clockenflap（香港 🇭🇰） | AE24: Ultra Music Festival（マイアミ 🇺🇸） | AJ24: Coachella Valley Music & Arts Festival（カリフォルニア 🇺🇸） | AQ24: Primavera Sound Barcelona（バルセロナ 🇪🇸） | AS24: Glastonbury Festival（ピルトン 🇬🇧） | AU24: Montreux Jazz Festival（モントルー 🇨🇭） | AV24: Tomorrowland（ブーム 🇧🇪） | AW24: Fuji Rock Festival（新潟 🇯🇵） | AX24: Lollapalooza Chicago（シカゴ 🇺🇸） | AY24: Sziget Festival（ブダペスト 🇭🇺） | AZ24: Summer Sonic（東京・大阪 🇯🇵）
B25: Birthday legend
B26: R.I.P legend

Sheet 中期３カ年
C2: 項目
B3: シーズン名称 | D3: 2026 | E3: 2027 | F3: 2028 | G3: 2029 | H3: 2030
B4: 期間 | D4: 1 | E4: 2 | F4: 3 | G4: 4 | H4: 5
B5: 売上（万円） | D5: 0 | E5: =E6*E7 -> 50 | F5: =F6*F7 -> 200 | G5: =G6*G7 -> 600 | H5: =H6*H7 -> 1500
C6: 単価 | D6: 0 | E6: 0.5 | F6: 0.5 | G6: 0.5 | H6: 0.5
C7: 個数 | D7: 0 | E7: 100 | F7: =E7*F8 -> 400 | G7: =F7*G8 -> 1200 | H7: =G7*H8 -> 3000
C8: 成長率 | E8: 1 | F8: 4 | G8: 3 | H8: 2.5
B9: 売上原価 | D9: 0 | E9: =E10*E11 -> 20 | F9: =F10*F11 -> 53.333333 | G9: =G10*G11 -> 150 | H9: =H10*H11 -> 375
C10: コスト | D10: 0 | E10: 0.1 | F10: 0.1 | G10: 0.1 | H10: 0.1
C11: 個数 | D11: 0 | E11: =E7/E12 -> 200 | F11: =F7/F12 -> 533.33333 | G11: =G7/G12 -> 1500 | H11: =H7/H12 -> 3750
C12: 消化率 | E12: 0.5 | F12: 0.75 | G12: 0.8 | H12: 0.8
B13: 粗利 | E13: =E5-E9 -> 30 | F13: =F5-F9 -> 146.66667 | G13: =G5-G9 -> 450 | H13: =H5-H9 -> 1125
B14: 固定費
C15: 家賃 | D15: 0 | E15: 0 | F15: 0 | G15: 0 | H15: 0
C16: サーバー | D16: 0 | E16: 0 | F16: 0 | G16: 0 | H16: 0
C17: ツール | D17: 0 | E17: 0 | F17: 0 | G17: 0 | H17: 0
C18: 通信費 | D18: 0 | E18: 0 | F18: 0 | G18: 0 | H18: 0
C19: 保険 | D19: 0 | E19: 0 | F19: 0 | G19: 0 | H19: 0
C20: 人件費 | D20: 0 | E20: 0 | F20: 0 | G20: 0 | H20: 0
B21: 広告販促費
B22: 営業利益
B23: 設備投資
B24: 融資
B25: 補助金

Sheet シーズン概要
F2: 項目 | AQ2: 内容
F3: 目標 | G3: ・キャッシュショートを避ける | W3: 単月100万達成!! | AQ3: なるべく早く単月100万達成
G4: ・売上で利益確保
G5: ・在庫処分でCF改善
F6: シーズンテーマ
F7: ターゲット | G7: 🎪Festival Conference（カジュアル）
G8: 🎤Artist-Live Conference（カジュアル）
G9: 📲Digital Listener Conf.（カジュアル）
F10: 備考 | G10: 水色セルの数値を変更する
H11: D1&D2 | I11: D3 | J11: D4
F12: シーズン名称 | G12: 25FW | H12: 25FW | I12: 25FW | J12: 25FW | K12: 25FW | L12: 25FW | M12: 25FW | N12: 26SS | O12: 26SS | P12: 26SS | Q12: 26SS | R12: 26SS | S12: 26SS | T12: 26FW | U12: 26FW | V12: 26FW | W12: 26FW | X12: 26FW | Y12: 26FW | Z12: 27SS | AA12: 27SS | AB12: 27SS | AC12: 27SS | AD12: 27SS | AE12: 27SS | AF12: 27FW | AG12: 27FW | AH12: 27FW | AI12: 27FW | AJ12: 27FW | AK12: 27FW | AL12: 28SS | AM12: 28SS | AN12: 28SS | AO12: 28SS | AQ12: 25FW | AR12: 26SS・26FW | AS12: 27SS・27FW | AT12: 28SS・28FW | AU12: 中長期
F13: 期間 | G13: 0ヶ月 | H13: 1ヶ月 | I13: ２ヶ月 | J13: ３ヶ月 | K13: ４ヶ月 | L13: ５ヶ月 | M13: ６ヶ月 | N13: 7ヶ月 | O13: 8ヶ月 | P13: 9ヶ月 | Q13: 10ヶ月 | R13: 11ヶ月 | S13: 12ヶ月 | T13: 13ヶ月 | U13: 14ヶ月 | V13: 15ヶ月 | W13: 16ヶ月 | X13: 17ヶ月 | Y13: 18ヶ月 | Z13: 19ヶ月 | AA13: 20ヶ月 | AB13: 21ヶ月 | AC13: 22ヶ月 | AD13: 23ヶ月 | AE13: 24ヶ月 | AF13: 25ヶ月 | AG13: 26ヶ月 | AH13: 27ヶ月 | AI13: 28ヶ月 | AJ13: 29ヶ月 | AK13: 30ヶ月 | AL13: 31ヶ月 | AM13: 32ヶ月 | AN13: 33ヶ月 | AO13: 34ヶ月 | AQ13: 2025/8-2026/2 | AR13: 2026/2-2027/2 | AS13: 2027/2-2028/2 | AT13: 2028/2-2029/2
B14: 【収入の部】 | F14: 【収入の部】
C15: [資金調達・外部入金] | F15: 資金調達・外部入金
D16: 元手資金（万円） | F16: 元手資金（万円） | G16: 300
D17: 融資額 | F17: 融資額
D18: 補助金入金 | F18: 補助金入金
D19: 助成金入金 | F19: 助成金入金
C20: [売上計画・進捗] | F20: 売上計画・進捗
D21: 成長率 | F21: 成長率 | H21: 1 | I21: 1.025 | AQ21: =(I21^6) -> 1.1596934 | AR21: =AR23/(AQ23*2) -> 1.1101022 | AS21: =AS23/AR23 -> 1.3448888
D22: 売上達成率 | F22: 売上達成率 | H22: 0.55 | I22: 1 | J22: =$I22 -> 1 | K22: =$I22 -> 1 | L22: =$I22 -> 1 | M22: =$I22 -> 1 | N22: =$I22 -> 1 | O22: =$I22 -> 1 | P22: =$I22 -> 1 | Q22: =$I22 -> 1 | ... AO22: =$I22 -> 1
D23: 新規売上目標（万円） | F23: 新規売上目標（万円） | G23: 0 | H23: 100 | I23: =(H24)*$I$21 -> 56.375 | J23: =(I24)*$I$21 -> 57.784375 | K23: =(J24)*$I$21 -> 59.228984 | L23: =(K24)*$I$21 -> 60.709709 | M23: =(L24)*$I$21 -> 62.227452 | N23: =(M24)*$I$21 -> 63.783138 | O23: =(N24)*$I$21 -> 65.377716 | P23: =(O24)*$I$21 -> 67.012159 | ... AO23: =(AN24)*$I$21 -> 124.2368 | AQ23: =SUM(H23:M23) -> 396.32552 | AR23: =SUM(N23:Y23) -> 879.92366 | AS23: =SUM(Z23:AK23) -> 1183.3995
D24: 実績予想売上 | F24: 実績予想売上 | G24: 0 | H24: =H23*H22 -> 55 | I24: =I23*I22 -> 56.375 | J24: =J23*J22 -> 57.784375 | K24: =K23*K22 -> 59.228984 | L24: =L23*L22 -> 60.709709 | M24: =M23*M22 -> 62.227452 | N24: =N23*N22 -> 63.783138 | O24: =O23*O22 -> 65.377716 | ... AO24: =AO23*AO22 -> 124.2368 | AQ24: =SUM(H24:M24) -> 351.32552 | AR24: =SUM(N24:Y24) -> 879.92366 | AS24: =SUM(Z24:AK24) -> 1183.3995
D25: 合算売上（新規+在庫） | F25: 合算売上（新規+在庫） | G25: =G24+G41 -> 0 | H25: =H24+H41 -> 55 | I25: =I24+I41 -> 65.739889 | J25: =J24+J41 -> 68.958275 | K25: =K24+K41 -> 63.828721 | L25: =L24+L41 -> 60.709709 | M25: =M24+M41 -> 62.227452 | N25: =N24+N41 -> 63.783138 | ... AO25: =AO24+AO41 -> 128.23007 | AQ25: =SUM(H25:M25) -> 376.46405 | AR25: =SUM(N25:Y25) -> 907.76728 | AS25: =SUM(Z25:AK25) -> 1224.7084
C26: [売上・利益管理] | F26: 売上・粗利管理
D27: 粗利（万円） | F27: 粗利（万円） | G27: 0 | H27: =H25-H34 -> 34.1 | I27: =I25-I34 -> 44.317389 | J27: =J25-J34 -> 47.000212 | K27: =K25-K34 -> 41.321707 | L27: =L25-L34 -> 37.64002 | M27: =M25-M34 -> 38.58102 | N27: =N25-N34 -> 39.545546 | O27: =O25-O34 -> 40.534184 | ... AO27: =AO25-AO34 -> 81.020089 | AQ27: =SUM(H27:M27) -> 242.96035 | AR27: =SUM(N27:Y27) -> 573.39628 | AS27: =SUM(Z27:AK27) -> 775.01663
D28: 粗利率 | F28: 粗利率 | H28: =ROUNDUP(H27/H25,3) -> 0.62 | I28: =ROUNDUP(I27/I25,3) -> 0.675 | J28: =ROUNDUP(J27/J25,3) -> 0.682 | K28: =ROUNDUP(K27/K25,3) -> 0.648 | L28: =ROUNDUP(L27/L25,3) -> 0.62 | M28: =ROUNDUP(M27/M25,3) -> 0.62 | N28: =ROUNDUP(N27/N25,3) -> 0.62 | O28: =ROUNDUP(O27/O25,3) -> 0.62 | ... AO28: =ROUNDUP(AO27/AO25,3) -> 0.632 | AQ28: =ROUNDUP(AQ27/AQ23,3) -> 0.614 | AR28: =ROUNDUP(AR27/AR23,3) -> 0.652 | AS28: =ROUNDUP(AS27/AS23,3) -> 0.655
D29: 原価率 | F29: 原価率 | G29: 0.38 | H29: 0.38 | I29: 0.38 | J29: 0.38 | K29: 0.38 | L29: 0.38 | M29: 0.38 | N29: 0.38 | O29: 0.38 | P29: 0.38 | Q29: 0.38 | R29: 0.38 | S29: 0.38 | T29: 0.38 | U29: 0.38 | V29: 0.38 | W29: 0.38 | X29: 0.38 | Y29: 0.38 | Z29: 0.38 | AA29: 0.38 | AB29: 0.38 | AC29: 0.38 | AD29: 0.38 | AE29: 0.38 | AF29: 0.38 | AG29: 0.38 | AH29: 0.38 | AI29: 0.38 | AJ29: 0.38 | AK29: 0.38 | AL29: 0.38 | AM29: 0.38 | AN29: 0.38 | AO29: 0.38 | AQ29: 0.38 | AR29: 0.38 | AS29: 0.38
C30: [在庫・原価管理] | F30: 在庫・原価管理
D31: 月初棚卸資産 | F31: 月初棚卸資産 | G31: 0 | H31: =G35 -> 46.91358 | I31: =H35 -> 52.461111 | J31: =I35 -> 34.735108 | K31: =J35 -> 12.628733 | L31: =K35 -> 7.1034756 | M31: =L35 -> 13.226912 | N31: =M35 -> 19.503434 | O31: =N35 -> 25.936869 | ... AN31: =AM35 -> 57.15095
D32: 繰越在庫高 | F32: 繰越在庫高 | H32: =H31+H33-(H34+H39) -> 52.461111 | I32: =I31+I33-(I34+I39) -> 34.735108 | J32: =J31+J33-(J34+J39) -> 12.628733 | K32: =K31+K33-(K34+K39) -> 7.1034756 | L32: =L31+L33-(L34+L39) -> 13.226912 | M32: =M31+M33-(M34+M39) -> 19.503434 | N32: =N31+N33-(N34+N39) -> 25.936869 | O32: =O31+O33-(O34+O39) -> 32.53114 | ... AO32: =AO31+AO33-(AO34+AO39) -> -47.209983
D33: 当月仕入高（万円） | F33: 当月仕入高（万円） | G33: =(H23/(H36*(1-H44)))*H29 -> 46.91358 | H33: =(I23/(I36*(1-I44)))*I29 -> 26.447531 | I33: =(J23/(J36*(1-J44)))*J29 -> 27.108719 | J33: =(K23/(K36*(1-K44)))*K29 -> 27.786437 | K33: =(L23/(L36*(1-L44)))*L29 -> 28.481098 | L33: =(M23/(M36*(1-M44)))*M29 -> 29.193125 | M33: =(N23/(N36*(1-N44)))*N29 -> 29.922954 | N33: =(O23/(O36*(1-O44)))*O29 -> 30.671027 | ... AN33: =(AO23/(AO36*(1-AO44)))*AO29 -> 58.28393 | AQ33: =SUM(H33:M33) -> 168.93986 | AR33: =SUM(N33:Y33) -> 423.12378 | AS33: =SUM(Z33:AK33) -> 569.05445
D34: 当月売上原価 | F34: 当月売上原価 | G34: 0 | H34: =MIN(H24*H29, G35+H33) -> 20.9 | I34: =MIN(I24*I29, H35+I33) -> 21.4225 | J34: =MIN(J24*J29, I35+J33) -> 21.958063 | K34: =MIN(K24*K29, J35+K33) -> 22.507014 | L34: =MIN(L24*L29, K35+L33) -> 23.069689 | M34: =MIN(M24*M29, L35+M33) -> 23.646432 | N34: =MIN(N24*N29, M35+N33) -> 24.237592 | O34: =MIN(O24*O29, N35+O33) -> 24.843532 | ... AO34: =MIN(AO24*AO29, AN35+AO33) -> 47.209983 | AQ34: =SUM(H34:M34) -> 133.5037 | AR34: =SUM(N34:Y34) -> 334.37099 | AS34: =SUM(Z34:AK34) -> 449.69181
D35: 月末棚卸資産（万円） | F35: 月末棚卸資産（万円） | G35: =G33+G31-G34-G39 -> 46.91358 | H35: =H33+H31-(H34+H39) -> 52.461111 | I35: =I33+I31-(I34+I39) -> 34.735108 | J35: =J33+J31-(J34+J39) -> 12.628733 | K35: =K33+K31-(K34+K39) -> 7.1034756 | L35: =L33+L31-(L34+L39) -> 13.226912 | M35: =M33+M31-(M34+M39) -> 19.503434 | N35: =N33+N31-(N34+N39) -> 25.936869 | O35: =O33+O31-(O34+O39) -> 32.53114 | ... AN35: =AN33+AN31-(AN34+AN39) -> 60.289016 | AQ35: =SUM(H35:M35) -> 139.65877 | AR35: =SUM(N35:Y35) -> 435.5245 | AS35: =SUM(Z35:AK35) -> 583.73039
D36: 消化率 | F36: 消化率 | G36: 0.9 | H36: 0.9 | I36: 0.9 | J36: 0.9 | K36: 0.9 | L36: 0.9 | M36: 0.9 | N36: 0.9 | O36: 0.9 | P36: 0.9 | Q36: 0.9 | R36: 0.9 | S36: 0.9 | T36: 0.9 | U36: 0.9 | V36: 0.9 | W36: 0.9 | X36: 0.9 | Y36: 0.9 | Z36: 0.9 | AA36: 0.9 | AB36: 0.9 | AC36: 0.9 | AD36: 0.9 | AE36: 0.9 | AF36: 0.9 | AG36: 0.9 | AH36: 0.9 | AI36: 0.9 | AJ36: 0.9 | AK36: 0.9 | AL36: 0.9 | AM36: 0.9 | AN36: 0.9 | AO36: 0.9 | AQ36: 0.9 | AR36: 0.9 | AS36: 0.9
C37: [在庫処分管理] | F37: 在庫処分管理
D38: 在庫処分対象額 | E38: ※適正10〜30% | F38: 在庫処分対象額 ※適正10-30% | G38: 0 | H38: =IF(H31-H34<0, 0, H31-H34) -> 26.01358 | I38: =IF(I31-I34<0, 0, I31-I34) -> 31.038611 | J38: =IF(J31-J34<0, 0, J31-J34) -> 12.777046 | K38: =IF(K31-K34<0, 0, K31-K34) -> 0 | L38: =IF(L31-L34<0, 0, L31-L34) -> 0 | M38: =IF(M31-M34<0, 0, M31-M34) -> 0 | N38: =IF(N31-N34<0, 0, N31-N34) -> 0 | O38: =IF(O31-O34<0, 0, O31-O34) -> 1.0933365 | ... AN38: =IF(AN31-AN34<0, 0, AN31-AN34) -> 11.09243
D39: 在庫処分原価 | F39: 在庫処分原価 | G39: 0 | H39: =G38*H43 -> 0 | I39: =H38*I43 -> 23.412222 | J39: =I38*J43 -> 27.93475 | K39: =J38*K43 -> 11.499341 | L39: =K38*L43 -> 0 | M39: =L38*M43 -> 0 | N39: =M38*N43 -> 0 | O39: =N38*O43 -> 0 | ... AO39: =AN38*AO43 -> 0
D40: 在庫販売割引率 | F40: 在庫販売割引率 | H40: 0.6 | I40: 0.6 | J40: 0.6 | K40: 0.6 | L40: 0.6 | M40: 0.6 | N40: 0.6 | O40: 0.6 | P40: 0.6 | Q40: 0.6 | R40: 0.6 | S40: 0.6 | T40: 0.6 | U40: 0.6 | V40: 0.6 | W40: 0.6 | X40: 0.6 | Y40: 0.6 | Z40: 0.6 | AA40: 0.6 | AB40: 0.6 | AC40: 0.6 | AD40: 0.6 | AE40: 0.6 | AF40: 0.6 | AG40: 0.6 | AH40: 0.6 | AI40: 0.6 | AJ40: 0.6 | AK40: 0.6 | AL40: 0.6 | AM40: 0.6 | AN40: 0.6
D41: 在庫処分売上 | F41: 在庫処分売上 | H41: 0 | I41: =I39*(1-I40) -> 9.3648889 | J41: =I38*(1-I40)*I43 -> 11.1739 | K41: =J38*(1-J40)*J43 -> 4.5997364 | L41: =K38*(1-K40)*K43 -> 0 | M41: =L38*(1-L40)*L43 -> 0 | N41: =M38*(1-M40)*M43 -> 0 | O41: =N38*(1-N40)*N43 -> 0 | P41: =O38*(1-O40)*O43 -> 0.39360113 | Q41: =P38*(1-P40)*P43 -> 2.5439469 | ... AO41: =AN38*(1-AN40)*AN43 -> 3.993275
...

Sheet Sheet1
A1: 【収入の部】
B2: [資金調達・外部入金]
C3: 元手資金（万円）
C4: 融資額
C5: 補助金入金
C6: 助成金入金
B8: [売上計画・進捗]
C9: 成長率
C10: 売上達成率
C11: 新規売上目標（万円）
C12: 実績予想売上
C13: 合算売上（新規+在庫）
B15: [売上・利益管理]
C16: 粗利（万円）
C17: 粗利率
C18: 原価率
B20: [在庫・原価管理]
C21: 月初棚卸資産
C22: 繰越在庫高
C23: 当月仕入高（万円）
C24: 当月売上原価
C25: 月末棚卸資産（万円）
C26: 消化率
B28: [在庫処分管理]
C29: 在庫処分対象額
C30: ※適正10〜30%
C31: 在庫処分原価
C32: 在庫販売割引率
C33: 在庫処分売上
C34: 在庫処分損失額
C35: 在庫処分率
C36: 割引率
A38: 【支出の部】
B39: [設備・初期費用]
C40: 3Dプリンター追加
D41: 台数
D42: Bambu Lab P2S Combo
D43: 防振脚座
D44: その他備品
D45: 配送料・搬入費
...

Sheet 投入計画
B3: DEL | C3: 商品投入月 | D3: 売上配分 | E3: 売上目標 | F3: 1ヶ月目 | G3: 2ヶ月目 | H3: 3ヶ月目 | I3: 4ヶ月目 | J3: 5ヶ月目 | K3: 6ヶ月目
B4: D1 | C4: 1ヶ月目頭 | D4: =広告!C5 -> 1 | E4: =広告!C6 -> 3620609 | F4: =$E$4*L4 -> 2172365.4 | G4: =$E$4*M4 -> 905152.25 | H4: =$E$4*N4 -> 543091.35 | I4: - | J4: - | K4: - | L4: 0.6 | M4: 0.25 | N4: 0.15 | O4: =SUM(L4:N4) -> 1
B5: D2 | C5: 1ヶ月目ケツ | D5: =広告!D5 -> 0 | E5: =広告!D6 -> 0 | F5: =$E$5*L5 -> 0 | G5: =$E$5*M5 -> 0 | H5: =$E$5*N5 -> 0 | I5: - | J5: - | K5: - | L5: 0.15 | M5: 0.6 | N5: 0.25 | O5: =SUM(L5:N5) -> 1
B6: D3 | C6: 2ヶ月目 | D6: =広告!E5 -> 0 | E6: =広告!E6 -> 0 | F6: - | G6: =$E$6*L6 -> 0 | H6: =$E$6*M6 -> 0 | I6: =$E$6*N6 -> 0 | J6: - | K6: - | L6: 0.3 | M6: 0.4 | N6: 0.3 | O6: =SUM(L6:N6) -> 1
B7: D4 | C7: 3ヶ月目 | D7: =広告!F5 -> 0 | E7: =広告!F6 -> 0 | F7: - | G7: - | H7: =$E$7*L7 -> 0 | I7: =$E$7*M7 -> 0 | J7: =$E$7*N7 -> 0 | K7: - | L7: 0.6 | M7: 0.25 | N7: 0.15 | O7: =SUM(L7:N7) -> 1
D8: =SUM(D4:D7) -> 1 | E8: =SUM(E4:E7) -> 3620609 | F8: =SUM(F4:F7) -> 2172365.4 | G8: =SUM(G4:G7) -> 905152.25 | H8: =SUM(H4:H7) -> 543091.35 | I8: =SUM(I4:I7) -> 0 | J8: =SUM(J4:J7) -> 0 | K8: =SUM(K4:K7) -> 0
C9: 単月目標（万円） | E9: =SUM(F9:K9) -> 351.32552 | F9: =シーズン概要!H24 -> 55 | G9: =シーズン概要!I24 -> 56.375 | H9: =シーズン概要!J24 -> 57.784375 | I9: =シーズン概要!K24 -> 59.228984 | J9: =シーズン概要!L24 -> 60.709709 | K9: =シーズン概要!M24 -> 62.227452
C10: 累積目標（万円） | F10: =F8/10000 -> 217.23654 | G10: =F10+G8/10000 -> 307.75176 | H10: =G10+H8/10000 -> 362.0609 | I10: =H10+I8/10000 -> 362.0609 | J10: =I10+J8/10000 -> 362.0609 | K10: =J10+K8/10000 -> 362.0609

Sheet 売上粗利計画
B2: IMAGE | C2: ブランド コード | D2: シーズン コード | E2: 回数 | F2: SKU コード | G2: STYLE NUMBER | H2: COLOR_CODE | I2: カテゴリ | J2: アイテム名 | K2: 生産枚数 | L2: ターゲット 上代_税抜 | M2: 定価 | N2: 売上予測 | O2: 消化率予測 | P2: 割引率 | Q2: 目標売上 | R2: 原価 | S2: 原価率 | T2: 製造コスト | U2: 粗利 | V2: 粗利率 | W2: DEL
C3: BW | D3: SS | E3: 1 | F3: _001 | G3: =売上粗利計画[[#This Row],[ブランド コード]]&売上粗利計画[[#This Row],[シーズン コード]]&売上粗利計画[[#This Row],[回数]]&売上粗利計画[[#This Row],[SKU コード]] -> BWSS1_001 | H3: WHITE | I3: TOPS | J3: HS Tee | K3: =SKUカラー!K3 -> 90 | L3: 6500 | M3: =ROUNDUP(売上粗利計画[[#This Row],[原価]]/売上粗利計画[[#This Row],[原価率]],0) -> 6905 | N3: =売上粗利計画[[#This Row],[生産枚数]]*売上粗利計画[[#This Row],[定価]] -> 621450 | O3: 0.9 | P3: 0.1 | Q3: =ROUNDUP(売上粗利計画[[#This Row],[生産枚数]]*売上粗利計画[[#This Row],[消化率予測]]*(売上粗利計画[[#This Row],[定価]]*(1-売上粗利計画[[#This Row],[割引率]])),0) -> 503375 | R3: 2900 | S3: 0.42 | T3: =売上粗利計画[[#This Row],[生産枚数]]*売上粗利計画[[#This Row],[原価]] -> 261000 | U3: =売上粗利計画[[#This Row],[目標売上]]-(売上粗利計画[[#This Row],[原価]]*売上粗利計画[[#This Row],[生産枚数]]*売上粗利計画[[#This Row],[消化率予測]]) -> 268475 | V3: =売上粗利計画[[#This Row],[粗利]]/売上粗利計画[[#This Row],[目標売上]] -> 0.53334989 | W3: D1
C4: BW | D4: SS | E4: 1 | F4: _001 | G4: =売上粗利計画[[#This Row],[ブランド コード]]&売上粗利計画[[#This Row],[シーズン コード]]&売上粗利計画[[#This Row],[回数]]&売上粗利計画[[#This Row],[SKU コード]] -> BWSS1_001 | H4: BLACK | I4: TOPS | J4: HS Tee | K4: =SKUカラー!K4 -> 162 | L4: 6500 | M4: =ROUNDUP(売上粗利計画[[#This Row],[原価]]/売上粗利計画[[#This Row],[原価率]],0) -> 6977 | N4: =売上粗利計画[[#This Row],[生産枚数]]*売上粗利計画[[#This Row],[定価]] -> 1130274 | O4: 0.9 | P4: 0.1 | Q4: =ROUNDUP(売上粗利計画[[#This Row],[生産枚数]]*売上粗利計画[[#This Row],[消化率予測]]*(売上粗利計画[[#This Row],[定価]]*(1-売上粗利計画[[#This Row],[割引率]])),0) -> 915522 | R4: 2930 | S4: 0.42 | T4: =売上粗利計画[[#This Row],[生産枚数]]*売上粗利計画[[#This Row],[原価]] -> 474660 | U4: =売上粗利計画[[#This Row],[目標売上]]-(売上粗利計画[[#This Row],[原価]]*売上粗利計画[[#This Row],[生産枚数]]*売上粗利計画[[#This Row],[消化率予測]]) -> 488328 | V4: =売上粗利計画[[#This Row],[粗利]]/売上粗利計画[[#This Row],[目標売上]] -> 0.53338751 | W4: D1
C5: BW | D5: SS | E5: 1 | F5: _002 | G5: =売上粗利計画[[#This Row],[ブランド コード]]&売上粗利計画[[#This Row],[シーズン コード]]&売上粗利計画[[#This Row],[回数]]&売上粗利計画[[#This Row],[SKU コード]] -> BWSS1_002 | H5: WHITE | I5: TOPS | J5: HS Tee | K5: =SKUカラー!K6 -> 90 | L5: 6500 | M5: =ROUNDUP(売上粗利計画[[#This Row],[原価]]/売上粗利計画[[#This Row],[原価率]],0) -> 6905 | N5: =売上粗利計画[[#This Row],[生産枚数]]*売上粗利計画[[#This Row],[定価]] -> 621450 | O5: 0.9 | P5: 0.1 | Q5: =ROUNDUP(売上粗利計画[[#This Row],[生産枚数]]*売上粗利計画[[#This Row],[消化率予測]]*(売上粗利計画[[#This Row],[定価]]*(1-売上粗利計画[[#This Row],[割引率]])),0) -> 503375 | R5: 2900 | S5: 0.42 | T5: =売上粗利計画[[#This Row],[生産枚数]]*売上粗利計画[[#This Row],[原価]] -> 261000 | U5: =売上粗利計画[[#This Row],[目標売上]]-(売上粗利計画[[#This Row],[原価]]*売上粗利計画[[#This Row],[生産枚数]]*売上粗利計画[[#This Row],[消化率予測]]) -> 268475 | V5: =売上粗利計画[[#This Row],[粗利]]/売上粗利計画[[#This Row],[目標売上]] -> 0.53334989 | W5: D1
C6: BW | D6: SS | E6: 1 | F6: _002 | G6: =売上粗利計画[[#This Row],[ブランド コード]]&売上粗利計画[[#This Row],[シーズン コード]]&売上粗利計画[[#This Row],[回数]]&売上粗利計画[[#This Row],[SKU コード]] -> BWSS1_002 | H6: BLACK | I6: TOPS | J6: HS Tee | K6: =SKUカラー!K7 -> 162 | L6: 6500 | M6: =ROUNDUP(売上粗利計画[[#This Row],[原価]]/売上粗利計画[[#This Row],[原価率]],0) -> 6977 | N6: =売上粗利計画[[#This Row],[生産枚数]]*売上粗利計画[[#This Row],[定価]] -> 1130274 | O6: 0.9 | P6: 0.1 | Q6: =ROUNDUP(売上粗利計画[[#This Row],[生産枚数]]*売上粗利計画[[#This Row],[消化率予測]]*(売上粗利計画[[#This Row],[定価]]*(1-売上粗利計画[[#This Row],[割引率]])),0) -> 915522 | R6: 2930 | S6: 0.42 | T6: =売上粗利計画[[#This Row],[生産枚数]]*売上粗利計画[[#This Row],[原価]] -> 474660 | U6: =売上粗利計画[[#This Row],[目標売上]]-(売上粗利計画[[#This Row],[原価]]*売上粗利計画[[#This Row],[生産枚数]]*売上粗利計画[[#This Row],[消化率予測]]) -> 488328 | V6: =売上粗利計画[[#This Row],[粗利]]/売上粗利計画[[#This Row],[目標売上]] -> 0.53338751 | W6: D1
C7: BW | D7: FW | E7: 1 | F7: _003 | G7: =売上粗利計画[[#This Row],[ブランド コード]]&売上粗利計画[[#This Row],[シーズン コード]]&売上粗利計画[[#This Row],[回数]]&売上粗利計画[[#This Row],[SKU コード]] -> BWFW1_003 | H7: BLACK | I7: TOPS | J7: P/O Parka | K7: =SKUカラー!K9 -> 99 | L7: 10000 | M7: =ROUNDUP(売上粗利計画[[#This Row],[原価]]/売上粗利計画[[#This Row],[原価率]],0) -> 9762 | N7: =売上粗利計画[[#This Row],[生産枚数]]*売上粗利計画[[#This Row],[定価]] -> 966438 | O7: 0.9 | P7: 0.1 | Q7: =ROUNDUP(売上粗利計画[[#This Row],[生産枚数]]*売上粗利計画[[#This Row],[消化率予測]]*(売上粗利計画[[#This Row],[定価]]*(1-売上粗利計画[[#This Row],[割引率]])),0) -> 782815 | R7: 4100 | S7: 0.42 | T7: =売上粗利計画[[#This Row],[生産枚数]]*売上粗利計画[[#This Row],[原価]] -> 405900 | U7: =売上粗利計画[[#This Row],[目標売上]]-(売上粗利計画[[#This Row],[原価]]*売上粗利計画[[#This Row],[生産枚数]]*売上粗利計画[[#This Row],[消化率予測]]) -> 417505 | V7: =売上粗利計画[[#This Row],[粗利]]/売上粗利計画[[#This Row],[目標売上]] -> 0.53333802 | W7: D1
K8: =SUBTOTAL(109,売上粗利計画[生産枚数]) -> 603 | L8: =MEDIAN(売上粗利計画[ターゲット 上代_税抜]) -> 6500 | N8: =SUBTOTAL(109,売上粗利計画[売上予測]) -> 4469886 | O8: =MEDIAN(売上粗利計画[[#Headers],[#Data],[消化率予測]]) -> 0.9 | P8: =MEDIAN(売上粗利計画[[#Headers],[#Data],[割引率]]) -> 0.1 | Q8: =SUBTOTAL(109,売上粗利計画[目標売上]) -> 3620609 | S8: =MEDIAN(売上粗利計画[原価率]) -> 0.42 | T8: =SUBTOTAL(109,売上粗利計画[製造コスト]) -> 1877220 | U8: =SUBTOTAL(109,売上粗利計画[粗利]) -> 1931111

Sheet 広告
B2: 広告予算配分 | F2: ROAS | G2: 2.5
B4: 施策 | C4: D1 | D4: D2 | E4: D3 | F4: D4 | G4: 合計
B5: 売上配分 | C5: =C6/$G$6 -> 1 | D5: =D6/$G$6 -> 0 | E5: =E6/$G$6 -> 0 | F5: =F6/$G$6 -> 0 | G5: =SUM(C5:F5) -> 1
B6: 売り上げ目標 | C6: =SUMIF(売上粗利計画!$W$3:$W$7,C4,売上粗利計画!$Q$3:$Q$7) -> 3620609 | D6: =SUMIF(売上粗利計画!$W$3:$W$7,D4,売上粗利計画!$Q$3:$Q$7) -> 0 | E6: =SUMIF(売上粗利計画!$W$3:$W$7,E4,売上粗利計画!$Q$3:$Q$7) -> 0 | F6: =SUMIF(売上粗利計画!$W$3:$W$7,F4,売上粗利計画!$Q$3:$Q$7) -> 0 | G6: =SUM(C6:F6) -> 3620609
B7: 広告予算配分 | C7: =C6/$G$2 -> 1448243.6 | D7: =D6/$G$2 -> 0 | E7: =E6/$G$2 -> 0 | F7: =F6/$G$2 -> 0 | G7: =SUM(C7:F7) -> 1448243.6
B8: 内訳
B9: プレスリリース
B10: ティザー | C10: 30000 | D10: 30000 | E10: 30000 | F10: 30000
B11: 期中 | C11: 30000 | D11: 30000 | E11: 30000 | F11: 30000
B12: 広告 | C12: =C7-(C10+C11) -> 1388243.6 | D12: =D7-(D10+D11) -> -60000 | E12: =E7-(E10+E11) -> -60000 | F12: =F7-(F10+F11) -> -60000
B13: FB広告 | C13: ※A/Bテストします
B14: ティザー（10d） | C14: =C$12/5 -> 277648.72 | D14: =D$12/5 -> -12000 | E14: =E$12/5 -> -12000 | F14: =F$12/5 -> -12000
B15: 期中(10d) | C15: =C$12/5 -> 277648.72 | D15: =D$12/5 -> -12000 | E15: =E$12/5 -> -12000 | F15: =F$12/5 -> -12000
B16: Tiktok広告 | C16: ※A/Bテストします
B17: ティザー | C17: =C$12/5 -> 277648.72 | D17: =D$12/5 -> -12000 | E17: =E$12/5 -> -12000 | F17: =F$12/5 -> -12000
B18: 期中 | C18: =C$12/5 -> 277648.72 | D18: =D$12/5 -> -12000 | E18: =E$12/5 -> -12000 | F18: =F$12/5 -> -12000
B19: Pinterest
B20: 期中 | C20: =C$12/5 -> 277648.72 | D20: =D$12/5 -> -12000 | E20: =E$12/5 -> -12000 | F20: =F$12/5 -> -12000 | G20: =SUM(C20:F20) -> 241648.72
B22: 制作費 | C22: D1 | D22: D2 | E22: D3 | F22: D4
B23: LP製作 | C23: 150000 | D23: 150000 | E23: 150000 | F23: 150000 | G23: =SUM(C23:F23) -> 600000
B24: プレスリリース | C24: 6000 | D24: 6000 | E24: 6000 | F24: 6000 | G24: =SUM(C24:F24) -> 24000
B25: 撮影（物撮り） | C25: 50000 | D25: 50000 | E25: 50000 | F25: 50000 | G25: =SUM(C25:F25) -> 200000 | H25: ※最安です
B26: 撮影（ルック）
B27: 白ホリ | C27: 100000 | G27: 100000 | H27: =SUM(G27:G31) -> 480000
B28: モデル（2人） | C28: 80000 | G28: 80000
B29: カメラマン | C29: 150000 | G29: 150000 | H29: ※インクルード
B30: スタイリスト | C30: 100000 | G30: 100000
B31: メイク | C31: 50000 | G31: 50000
B32: SNS運用（IG,TK） | C32: 120000 | D32: 120000 | E32: 120000 | F32: 120000 | G32: =SUM(C32:F32) -> 480000
C33: =SUM(C23:C32) -> 806000 | D33: =SUM(D23:D32) -> 326000 | E33: =SUM(E23:E32) -> 326000 | F33: =SUM(F23:F32) -> 326000 | G33: =SUM(G23:G32) -> 1784000

Sheet SKUマスタ
B2: STYLE NUMBER | C2: 商品名 | D2: カテゴリ | E2: カラー数 | F2: サイズ展開 | G2: 定価 | H2: 原価 | I2: 在庫数 | J2: DEL | K2: 備考
B3: =売上粗利計画[[#This Row],[ブランド コード]]&売上粗利計画[[#This Row],[シーズン コード]]&売上粗利計画[[#This Row],[回数]]&売上粗利計画[[#This Row],[SKU コード]] -> BWSS1_001 | C3: =売上粗利計画[[#This Row],[アイテム名]] -> HS Tee | D3: =売上粗利計画[[#This Row],[カテゴリ]] -> TOPS | E3: 2 | F3: S, M, L,XL | G3: =売上粗利計画[[#This Row],[定価]] -> 6905 | H3: =売上粗利計画[[#This Row],[原価]] -> 2900 | I3: =売上粗利計画[[#This Row],[生産枚数]] -> 90 | J3: =売上粗利計画[[#This Row],[DEL]] -> D1
B4: =売上粗利計画[[#This Row],[ブランド コード]]&売上粗利計画[[#This Row],[シーズン コード]]&売上粗利計画[[#This Row],[回数]]&売上粗利計画[[#This Row],[SKU コード]] -> BWSS1_001 | C4: =売上粗利計画[[#This Row],[アイテム名]] -> HS Tee | D4: =売上粗利計画[[#This Row],[カテゴリ]] -> TOPS | E4: 2 | F4: S, M, L,XL | G4: =売上粗利計画[[#This Row],[定価]] -> 6977 | H4: =売上粗利計画[[#This Row],[原価]] -> 2930 | I4: =売上粗利計画[[#This Row],[生産枚数]] -> 162 | J4: =売上粗利計画[[#This Row],[DEL]] -> D1
B5: =売上粗利計画[[#This Row],[ブランド コード]]&売上粗利計画[[#This Row],[シーズン コード]]&売上粗利計画[[#This Row],[回数]]&売上粗利計画[[#This Row],[SKU コード]] -> BWSS1_002 | C5: =売上粗利計画[[#This Row],[アイテム名]] -> HS Tee | D5: =売上粗利計画[[#This Row],[カテゴリ]] -> TOPS | E5: 2 | F5: S, M, L,XL | G5: =売上粗利計画[[#This Row],[定価]] -> 6905 | H5: =売上粗利計画[[#This Row],[原価]] -> 2900 | I5: =売上粗利計画[[#This Row],[生産枚数]] -> 90 | J5: =売上粗利計画[[#This Row],[DEL]] -> D1
B6: =売上粗利計画[[#This Row],[ブランド コード]]&売上粗利計画[[#This Row],[シーズン コード]]&売上粗利計画[[#This Row],[回数]]&売上粗利計画[[#This Row],[SKU コード]] -> BWSS1_002 | C6: =売上粗利計画[[#This Row],[アイテム名]] -> HS Tee | D6: =売上粗利計画[[#This Row],[カテゴリ]] -> TOPS | E6: 3 | F6: S, M, L | G6: =売上粗利計画[[#This Row],[定価]] -> 6977 | H6: =売上粗利計画[[#This Row],[原価]] -> 2930 | I6: =売上粗利計画[[#This Row],[生産枚数]] -> 162 | J6: =売上粗利計画[[#This Row],[DEL]] -> D1
B7: =売上粗利計画[[#This Row],[ブランド コード]]&売上粗利計画[[#This Row],[シーズン コード]]&売上粗利計画[[#This Row],[回数]]&売上粗利計画[[#This Row],[SKU コード]] -> BWFW1_003 | C7: =売上粗利計画[[#This Row],[アイテム名]] -> P/O Parka | D7: =売上粗利計画[[#This Row],[カテゴリ]] -> TOPS | E7: 4 | F7: F | G7: =売上粗利計画[[#This Row],[定価]] -> 9762 | H7: =売上粗利計画[[#This Row],[原価]] -> 4100 | I7: =売上粗利計画[[#This Row],[生産枚数]] -> 99 | J7: =売上粗利計画[[#This Row],[DEL]] -> D1
I8: =SUM(テーブル2[在庫数]) -> 603

Sheet SKUカラー
B2: STYLE NUMBER | C2: 商品名 | D2: カテゴリ | E2: COLOR_CODE | F2: S | G2: M | H2: L | I2: XL | J2: UNIT | K2: 数量 | L2: 各合計数量 | M2: 上代(税抜) | N2: unit cost 原価 | O2: 在庫数 | P2: DEL | Q2: 備考
B3: BWSS1_001 | C3: HS Tee | D3: =売上粗利計画[[#This Row],[カテゴリ]] -> TOPS | E3: WHITE | F3: 1 | G3: 3 | H3: 3 | I3: 2 | J3: 10 | K3: =SUM(SKUカラー[[#This Row],[S]:[XL]])*SKUカラー[[#This Row],[UNIT]] -> 90 | M3: =SKUマスタ!G3 -> 6905 | N3: =SKUマスタ!H3 -> 2900 | O3: =SKUマスタ!I3 -> 90 | P3: =売上粗利計画[[#This Row],[DEL]] -> D1
B4: BWSS1_001 | C4: HS Tee | D4: =売上粗利計画[[#This Row],[カテゴリ]] -> TOPS | E4: BLACK | F4: 1 | G4: 3 | H4: 3 | I4: 2 | J4: 18 | K4: =SUM(SKUカラー[[#This Row],[S]:[XL]])*SKUカラー[[#This Row],[UNIT]] -> 162 | M4: =SKUマスタ!G3 -> 6905 | N4: =SKUマスタ!H4 -> 2930 | O4: =SKUマスタ!I3 -> 90 | P4: =売上粗利計画[[#This Row],[DEL]] -> D1
B5: BWSS1_001 | L5: =SUM($K3:$K4) -> 252
B6: BWSS1_002 | C6: LS Tee | D6: TOPS | E6: WHITE | F6: 1 | G6: 3 | H6: 3 | I6: 2 | J6: 10 | K6: =SUM(SKUカラー[[#This Row],[S]:[XL]])*SKUカラー[[#This Row],[UNIT]] -> 90 | M6: =SKUマスタ!G4 -> 6977 | N6: =SKUマスタ!H5 -> 2900 | O6: =SKUマスタ!I4 -> 162 | P6: =売上粗利計画[[#This Row],[DEL]] -> D1
B7: BWSS1_002 | C7: LS Tee | D7: TOPS | E7: BLACK | F7: 1 | G7: 3 | H7: 3 | I7: 2 | J7: 18 | K7: =SUM(SKUカラー[[#This Row],[S]:[XL]])*SKUカラー[[#This Row],[UNIT]] -> 162 | M7: =SKUマスタ!G4 -> 6977 | N7: =SKUマスタ!H6 -> 2930 | O7: =SKUマスタ!I4 -> 162 | P7: =売上粗利計画[[#This Row],[DEL]] -> D1
B8: BWSS1_002 | L8: =SUM($K6:$K7) -> 252
B9: BWFW1_003 | C9: P/O Parka | D9: =売上粗利計画!I7 -> TOPS | E9: BLACK | F9: 1 | G9: 3 | H9: 3 | I9: 2 | J9: 11 | K9: =SUM(SKUカラー[[#This Row],[S]:[XL]])*SKUカラー[[#This Row],[UNIT]] -> 99 | M9: =SKUマスタ!G5 -> 6905 | N9: =SKUマスタ!H7 -> 4100 | O9: =SKUマスタ!I5 -> 90 | P9: =売上粗利計画!W7 -> D1
L10: =SUM($K9) -> 99
O12: =SUM(SKUカラー[在庫数]) -> 594
B14: JANコード申請 | C14: https://www.gs1jp.org/code/jan/jan_apply.html

Sheet 発注書
B2: Collection Name | C2: STYLE NUMBER | D2: SKU | E2: ITEM_NAME | F2: CATEGORY | G2: COLOR_CODE | H2: SIZE | I2: DEL | J2: UNITS PER PACK | K2: RETAIL PRICE(JPY) | L2: WHSL PRICE(JPY)
B3: Promotion_Line | C3: =SKUマスタ!$B$3 -> BWSS1_001 | D3: =テーブル1[[#This Row],[STYLE NUMBER]]&"-"& _xlfn.XLOOKUP(G3, カラーコード!$C$2:$C$50, カラーコード!$D$2:$D$50,"未登録") &"-"&テーブル1[[#This Row],[SIZE]] -> BWSS1_001-WH-S | E3: =SKUマスタ!$C$3 -> HS Tee | F3: =SKUマスタ!$D$3 -> TOPS | G3: WHITE | H3: S | I3: =SKUマスタ!$J$3 -> D1 | J3: 1 | K3: =SKUマスタ!$G$3*110% -> 7595.5 | L3: =テーブル1[[#This Row],[RETAIL PRICE(JPY)]]*50% -> 3797.75
B4: Promotion_Line | C4: =SKUマスタ!$B$3 -> BWSS1_001 | D4: =テーブル1[[#This Row],[STYLE NUMBER]]&"-"& _xlfn.XLOOKUP(G4, カラーコード!$C$2:$C$50, カラーコード!$D$2:$D$50,"未登録") &"-"&テーブル1[[#This Row],[SIZE]] -> BWSS1_001-WH-M | E4: =SKUマスタ!$C$3 -> HS Tee | F4: =SKUマスタ!$D$3 -> TOPS | G4: WHITE | H4: M | I4: =SKUマスタ!$J$3 -> D1 | J4: 1 | K4: =SKUマスタ!$G$3*110% -> 7595.5 | L4: =テーブル1[[#This Row],[RETAIL PRICE(JPY)]]*50% -> 3797.75
B5: Promotion_Line | C5: =SKUマスタ!$B$3 -> BWSS1_001 | D5: =テーブル1[[#This Row],[STYLE NUMBER]]&"-"& _xlfn.XLOOKUP(G5, カラーコード!$C$2:$C$50, カラーコード!$D$2:$D$50,"未登録") &"-"&テーブル1[[#This Row],[SIZE]] -> BWSS1_001-WH-L | E5: =SKUマスタ!$C$3 -> HS Tee | F5: =SKUマスタ!$D$3 -> TOPS | G5: WHITE | H5: L | I5: =SKUマスタ!$J$3 -> D1 | J5: 1 | K5: =SKUマスタ!$G$3*110% -> 7595.5 | L5: =テーブル1[[#This Row],[RETAIL PRICE(JPY)]]*50% -> 3797.75
B6: Promotion_Line | C6: =SKUマスタ!$B$3 -> BWSS1_001 | D6: =テーブル1[[#This Row],[STYLE NUMBER]]&"-"& _xlfn.XLOOKUP(G6, カラーコード!$C$2:$C$50, カラーコード!$D$2:$D$50,"未登録") &"-"&テーブル1[[#This Row],[SIZE]] -> BWSS1_001-WH-XL | E6: =SKUマスタ!$C$3 -> HS Tee | F6: =SKUマスタ!$D$3 -> TOPS | G6: WHITE | H6: XL | I6: =SKUマスタ!$J$3 -> D1 | J6: 1 | K6: =SKUマスタ!$G$3*110% -> 7595.5 | L6: =テーブル1[[#This Row],[RETAIL PRICE(JPY)]]*50% -> 3797.75
B7: Promotion_Line | C7: =SKUマスタ!$B$3 -> BWSS1_001 | D7: =テーブル1[[#This Row],[STYLE NUMBER]]&"-"& _xlfn.XLOOKUP(G7, カラーコード!$C$2:$C$50, カラーコード!$D$2:$D$50,"未登録") &"-"&テーブル1[[#This Row],[SIZE]] -> BWSS1_001-BK-S | E7: =SKUマスタ!$C$3 -> HS Tee | F7: =SKUマスタ!$D$3 -> TOPS | G7: BLACK | H7: S | I7: =SKUマスタ!$J$3 -> D1 | J7: 1 | K7: =SKUマスタ!$G$3*110% -> 7595.5 | L7: =テーブル1[[#This Row],[RETAIL PRICE(JPY)]]*50% -> 3797.75
B8: Promotion_Line | C8: =SKUマスタ!$B$3 -> BWSS1_001 | D8: =テーブル1[[#This Row],[STYLE NUMBER]]&"-"& _xlfn.XLOOKUP(G8, カラーコード!$C$2:$C$50, カラーコード!$D$2:$D$50,"未登録") &"-"&テーブル1[[#This Row],[SIZE]] -> BWSS1_001-BK-M | E8: =SKUマスタ!$C$3 -> HS Tee | F8: =SKUマスタ!$D$3 -> TOPS | G8: BLACK | H8: M | I8: =SKUマスタ!$J$3 -> D1 | J8: 1 | K8: =SKUマスタ!$G$3*110% -> 7595.5 | L8: =テーブル1[[#This Row],[RETAIL PRICE(JPY)]]*50% -> 3797.75
B9: Promotion_Line | C9: =SKUマスタ!$B$3 -> BWSS1_001 | D9: =テーブル1[[#This Row],[STYLE NUMBER]]&"-"& _xlfn.XLOOKUP(G9, カラーコード!$C$2:$C$50, カラーコード!$D$2:$D$50,"未登録") &"-"&テーブル1[[#This Row],[SIZE]] -> BWSS1_001-BK-L | E9: =SKUマスタ!$C$3 -> HS Tee | F9: =SKUマスタ!$D$3 -> TOPS | G9: BLACK | H9: L | I9: =SKUマスタ!$J$3 -> D1 | J9: 1 | K9: =SKUマスタ!$G$3*110% -> 7595.5 | L9: =テーブル1[[#This Row],[RETAIL PRICE(JPY)]]*50% -> 3797.75
B10: Promotion_Line | C10: =SKUマスタ!$B$3 -> BWSS1_001 | D10: =テーブル1[[#This Row],[STYLE NUMBER]]&"-"& _xlfn.XLOOKUP(G10, カラーコード!$C$2:$C$50, カラーコード!$D$2:$D$50,"未登録") &"-"&テーブル1[[#This Row],[SIZE]] -> BWSS1_001-BK-XL | E10: =SKUマスタ!$C$3 -> HS Tee | F10: =SKUマスタ!$D$3 -> TOPS | G10: BLACK | H10: XL | I10: =SKUマスタ!$J$3 -> D1 | J10: 1 | K10: =SKUマスタ!$G$3*110% -> 7595.5 | L10: =テーブル1[[#This Row],[RETAIL PRICE(JPY)]]*50% -> 3797.75
B11: Promotion_Line | C11: =SKUマスタ!$B$3 -> BWSS1_001 | D11: =テーブル1[[#This Row],[STYLE NUMBER]]&"-"& _xlfn.XLOOKUP(G11, カラーコード!$C$2:$C$50, カラーコード!$D$2:$D$50,"未登録") &"-"&テーブル1[[#This Row],[SIZE]] -> BWSS1_001-WH-S | E11: =SKUマスタ!$C$3 -> HS Tee | F11: =SKUマスタ!$D$3 -> TOPS | G11: WHITE | H11: S | I11: =SKUマスタ!$J$3 -> D1 | J11: 1 | K11: =SKUマスタ!$G$3*110% -> 7595.5 | L11: =テーブル1[[#This Row],[RETAIL PRICE(JPY)]]*50% -> 3797.75
B12: Promotion_Line | C12: =SKUマスタ!$B$3 -> BWSS1_001 | D12: =テーブル1[[#This Row],[STYLE NUMBER]]&"-"& _xlfn.XLOOKUP(G12, カラーコード!$C$2:$C$50, カラーコード!$D$2:$D$50,"未登録") &"-"&テーブル1[[#This Row],[SIZE]] -> BWSS1_001-WH-M | E12: =SKUマスタ!$C$3 -> HS Tee | F12: =SKUマスタ!$D$3 -> TOPS | G12: WHITE | H12: M | I12: =SKUマスタ!$J$3 -> D1 | J12: 1 | K12: =SKUマスタ!$G$3*110% -> 7595.5 | L12: =テーブル1[[#This Row],[RETAIL PRICE(JPY)]]*50% -> 3797.75
B13: Promotion_Line | C13: =SKUマスタ!$B$3 -> BWSS1_001 | D13: =テーブル1[[#This Row],[STYLE NUMBER]]&"-"& _xlfn.XLOOKUP(G13, カラーコード!$C$2:$C$50, カラーコード!$D$2:$D$50,"未登録") &"-"&テーブル1[[#This Row],[SIZE]] -> BWSS1_001-WH-L | E13: =SKUマスタ!$C$3 -> HS Tee | F13: =SKUマスタ!$D$3 -> TOPS | G13: WHITE | H13: L | I13: =SKUマスタ!$J$3 -> D1 | J13: 1 | K13: =SKUマスタ!$G$3*110% -> 7595.5 | L13: =テーブル1[[#This Row],[RETAIL PRICE(JPY)]]*50% -> 3797.75
B14: Promotion_Line | C14: =SKUマスタ!$B$3 -> BWSS1_001 | D14: =テーブル1[[#This Row],[STYLE NUMBER]]&"-"& _xlfn.XLOOKUP(G14, カラーコード!$C$2:$C$50, カラーコード!$D$2:$D$50,"未登録") &"-"&テーブル1[[#This Row],[SIZE]] -> BWSS1_001-WH-XL | E14: =SKUマスタ!$C$3 -> HS Tee | F14: =SKUマスタ!$D$3 -> TOPS | G14: WHITE | H14: XL | I14: =SKUマスタ!$J$3 -> D1 | J14: 1 | K14: =SKUマスタ!$G$3*110% -> 7595.5 | L14: =テーブル1[[#This Row],[RETAIL PRICE(JPY)]]*50% -> 3797.75
B15: Promotion_Line | C15: =SKUマスタ!$B$4 -> BWSS1_001 | D15: =テーブル1[[#This Row],[STYLE NUMBER]]&"-"& _xlfn.XLOOKUP(G15, カラーコード!$C$2:$C$50, カラーコード!$D$2:$D$50,"未登録") &"-"&テーブル1[[#This Row],[SIZE]] -> BWSS1_001-BK-S | E15: =SKUマスタ!$C$4 -> HS Tee | F15: =SKUマスタ!$D$4 -> TOPS | G15: BLACK | H15: S | I15: =SKUマスタ!$J$4 -> D1 | J15: 1 | K15: =SKUマスタ!$G$4*110% -> 7674.7 | L15: =テーブル1[[#This Row],[RETAIL PRICE(JPY)]]*50% -> 3837.35
B16: Promotion_Line | C16: =SKUマスタ!$B$4 -> BWSS1_001 | D16: =テーブル1[[#This Row],[STYLE NUMBER]]&"-"& _xlfn.XLOOKUP(G16, カラーコード!$C$2:$C$50, カラーコード!$D$2:$D$50,"未登録") &"-"&テーブル1[[#This Row],[SIZE]] -> BWSS1_001-BK-M | E16: =SKUマスタ!$C$4 -> HS Tee | F16: =SKUマスタ!$D$4 -> TOPS | G16: BLACK | H16: M | I16: =SKUマスタ!$J$4 -> D1 | J16: 1 | K16: =SKUマスタ!$G$4*110% -> 7674.7 | L16: =テーブル1[[#This Row],[RETAIL PRICE(JPY)]]*50% -> 3837.35
B17: Promotion_Line | C17: =SKUマスタ!$B$4 -> BWSS1_001 | D17: =テーブル1[[#This Row],[STYLE NUMBER]]&"-"& _xlfn.XLOOKUP(G17, カラーコード!$C$2:$C$50, カラーコード!$D$2:$D$50,"未登録") &"-"&テーブル1[[#This Row],[SIZE]] -> BWSS1_001-BK-L | E17: =SKUマスタ!$C$4 -> HS Tee | F17: =SKUマスタ!$D$4 -> TOPS | G17: BLACK | H17: L | I17: =SKUマスタ!$J$4 -> D1 | J17: 1 | K17: =SKUマスタ!$G$4*110% -> 7674.7 | L17: =テーブル1[[#This Row],[RETAIL PRICE(JPY)]]*50% -> 3837.35
B18: Promotion_Line | C18: =SKUマスタ!$B$4 -> BWSS1_001 | D18: =テーブル1[[#This Row],[STYLE NUMBER]]&"-"& _xlfn.XLOOKUP(G18, カラーコード!$C$2:$C$50, カラーコード!$D$2:$D$50,"未登録") &"-"&テーブル1[[#This Row],[SIZE]] -> BWSS1_001-BK-XL | E18: =SKUマスタ!$C$4 -> HS Tee | F18: =SKUマスタ!$D$4 -> TOPS | G18: BLACK | H18: XL | I18: =SKUマスタ!$J$4 -> D1 | J18: 1 | K18: =SKUマスタ!$G$4*110% -> 7674.7 | L18: =テーブル1[[#This Row],[RETAIL PRICE(JPY)]]*50% -> 3837.35
B19: Promotion_Line | C19: =SKUマスタ!$B$5 -> BWSS1_002 | D19: =テーブル1[[#This Row],[STYLE NUMBER]]&"-"& _xlfn.XLOOKUP(G19, カラーコード!$C$2:$C$50, カラーコード!$D$2:$D$50,"未登録") &"-"&テーブル1[[#This Row],[SIZE]] -> BWSS1_002-BK-F | E19: =SKUマスタ!$C$5 -> HS Tee | F19: =SKUマスタ!$D$5 -> TOPS | G19: BLACK | H19: F | I19: =SKUマスタ!$J$5 -> D1 | J19: 1 | K19: =SKUマスタ!$G$5*110% -> 7595.5 | L19: =テーブル1[[#This Row],[RETAIL PRICE(JPY)]]*50% -> 3797.75
B20: Promotion_Line | C20: =SKUマスタ!$B$5 -> BWSS1_002 | D20: =テーブル1[[#This Row],[STYLE NUMBER]]&"-"& _xlfn.XLOOKUP(G20, カラーコード!$C$2:$C$50, カラーコード!$D$2:$D$50,"未登録") &"-"&テーブル1[[#This Row],[SIZE]] -> BWSS1_002-BK-F | E20: =SKUマスタ!$C$5 -> HS Tee | F20: =SKUマスタ!$D$5 -> TOPS | G20: BLACK | H20: F | I20: =SKUマスタ!$J$5 -> D1 | J20: 1 | K20: =SKUマスタ!$G$5*110% -> 7595.5 | L20: =テーブル1[[#This Row],[RETAIL PRICE(JPY)]]*50% -> 3797.75
B21: Promotion_Line | C21: =SKUマスタ!$B$5 -> BWSS1_002 | D21: =テーブル1[[#This Row],[STYLE NUMBER]]&"-"& _xlfn.XLOOKUP(G21, カラーコード!$C$2:$C$50, カラーコード!$D$2:$D$50,"未登録") &"-"&テーブル1[[#This Row],[SIZE]] -> BWSS1_002-BK-F | E21: =SKUマスタ!$C$5 -> HS Tee | F21: =SKUマスタ!$D$5 -> TOPS | G21: BLACK | H21: F | I21: =SKUマスタ!$J$5 -> D1 | J21: 1 | K21: =SKUマスタ!$G$5*110% -> 7595.5 | L21: =テーブル1[[#This Row],[RETAIL PRICE(JPY)]]*50% -> 3797.75
B22: Promotion_Line | C22: =SKUマスタ!$B$5 -> BWSS1_002 | D22: =テーブル1[[#This Row],[STYLE NUMBER]]&"-"& _xlfn.XLOOKUP(G22, カラーコード!$C$2:$C$50, カラーコード!$D$2:$D$50,"未登録") &"-"&テーブル1[[#This Row],[SIZE]] -> BWSS1_002-BK-F | E22: =SKUマスタ!$C$5 -> HS Tee | F22: =SKUマスタ!$D$5 -> TOPS | G22: BLACK | H22: F | I22: =SKUマスタ!$J$5 -> D1 | J22: 1 | K22: =SKUマスタ!$G$5*110% -> 7595.5 | L22: =テーブル1[[#This Row],[RETAIL PRICE(JPY)]]*50% -> 3797.75
C23: =SKUマスタ!$B$6 -> BWSS1_002 | D23: =テーブル1[[#This Row],[STYLE NUMBER]]&"-"& _xlfn.XLOOKUP(G23, カラーコード!$C$2:$C$50, カラーコード!$D$2:$D$50,"未登録") &"-"&テーブル1[[#This Row],[SIZE]] -> BWSS1_002-BK-S | E23: =SKUマスタ!$C$6 -> HS Tee | F23: =SKUマスタ!$D$6 -> TOPS | G23: BLACK | H23: S | I23: =SKUマスタ!$J$6 -> D1 | J23: 1 | K23: =SKUマスタ!$G$6*110% -> 7674.7 | L23: =テーブル1[[#This Row],[RETAIL PRICE(JPY)]]*50% -> 3837.35
C24: =SKUマスタ!$B$6 -> BWSS1_002 | D24: =テーブル1[[#This Row],[STYLE NUMBER]]&"-"& _xlfn.XLOOKUP(G24, カラーコード!$C$2:$C$50, カラーコード!$D$2:$D$50,"未登録") &"-"&テーブル1[[#This Row],[SIZE]] -> BWSS1_002-BK-M | E24: =SKUマスタ!$C$6 -> HS Tee | F24: =SKUマスタ!$D$6 -> TOPS | G24: BLACK | H24: M | I24: =SKUマスタ!$J$6 -> D1 | J24: 1 | K24: =SKUマスタ!$G$6*110% -> 7674.7 | L24: =テーブル1[[#This Row],[RETAIL PRICE(JPY)]]*50% -> 3837.35
C25: =SKUマスタ!$B$6 -> BWSS1_002 | D25: =テーブル1[[#This Row],[STYLE NUMBER]]&"-"& _xlfn.XLOOKUP(G25, カラーコード!$C$2:$C$50, カラーコード!$D$2:$D$50,"未登録") &"-"&テーブル1[[#This Row],[SIZE]] -> BWSS1_002-BK-L | E25: =SKUマスタ!$C$6 -> HS Tee | F25: =SKUマスタ!$D$6 -> TOPS | G25: BLACK | H25: L | I25: =SKUマスタ!$J$6 -> D1 | J25: 1 | K25: =SKUマスタ!$G$6*110% -> 7674.7 | L25: =テーブル1[[#This Row],[RETAIL PRICE(JPY)]]*50% -> 3837.35
C26: =SKUマスタ!$B$6 -> BWSS1_002 | D26: =テーブル1[[#This Row],[STYLE NUMBER]]&"-"& _xlfn.XLOOKUP(G26, カラーコード!$C$2:$C$50, カラーコード!$D$2:$D$50,"未登録") &"-"&テーブル1[[#This Row],[SIZE]] -> BWSS1_002-YG-S | E26: =SKUマスタ!$C$6 -> HS Tee | F26: =SKUマスタ!$D$6 -> TOPS | G26: YellowGreen | H26: S | I26: =SKUマスタ!$J$6 -> D1 | J26: 1 | K26: =SKUマスタ!$G$6*110% -> 7674.7 | L26: =テーブル1[[#This Row],[RETAIL PRICE(JPY)]]*50% -> 3837.35
C27: =SKUマスタ!$B$6 -> BWSS1_002 | D27: =テーブル1[[#This Row],[STYLE NUMBER]]&"-"& _xlfn.XLOOKUP(G27, カラーコード!$C$2:$C$50, カラーコード!$D$2:$D$50,"未登録") &"-"&テーブル1[[#This Row],[SIZE]] -> BWSS1_002-YG-M | E27: =SKUマスタ!$C$6 -> HS Tee | F27: =SKUマスタ!$D$6 -> TOPS | G27: YellowGreen | H27: M | I27: =SKUマスタ!$J$6 -> D1 | J27: 1 | K27: =SKUマスタ!$G$6*110% -> 7674.7 | L27: =テーブル1[[#This Row],[RETAIL PRICE(JPY)]]*50% -> 3837.35
C28: =SKUマスタ!$B$6 -> BWSS1_002 | D28: =テーブル1[[#This Row],[STYLE NUMBER]]&"-"& _xlfn.XLOOKUP(G28, カラーコード!$C$2:$C$50, カラーコード!$D$2:$D$50,"未登録") &"-"&テーブル1[[#This Row],[SIZE]] -> BWSS1_002-YG-L | E28: =SKUマスタ!$C$6 -> HS Tee | F28: =SKUマスタ!$D$6 -> TOPS | G28: YellowGreen | H28: L | I28: =SKUマスタ!$J$6 -> D1 | J28: 1 | K28: =SKUマスタ!$G$6*110% -> 7674.7 | L28: =テーブル1[[#This Row],[RETAIL PRICE(JPY)]]*50% -> 3837.35
C29: =SKUマスタ!$B$7 -> BWFW1_003 | D29: =テーブル1[[#This Row],[STYLE NUMBER]]&"-"& _xlfn.XLOOKUP(G29, カラーコード!$C$2:$C$50, カラーコード!$D$2:$D$50,"未登録") &"-"&テーブル1[[#This Row],[SIZE]] -> BWFW1_003-BK-S | E29: =SKUマスタ!$C$7 -> P/O Parka | F29: =SKUマスタ!$D$7 -> TOPS | G29: BLACK | H29: S | I29: =SKUマスタ!$J$7 -> D1 | J29: 1 | K29: =SKUマスタ!$G$7*110% -> 10738.2 | L29: =テーブル1[[#This Row],[RETAIL PRICE(JPY)]]*50% -> 5369.1
C30: =SKUマスタ!$B$7 -> BWFW1_003 | D30: =テーブル1[[#This Row],[STYLE NUMBER]]&"-"& _xlfn.XLOOKUP(G30, カラーコード!$C$2:$C$50, カラーコード!$D$2:$D$50,"未登録") &"-"&テーブル1[[#This Row],[SIZE]] -> BWFW1_003-BK-M | E30: =SKUマスタ!$C$7 -> P/O Parka | F30: =SKUマスタ!$D$7 -> TOPS | G30: BLACK | H30: M | I30: =SKUマスタ!$J$7 -> D1 | J30: 1 | K30: =SKUマスタ!$G$7*110% -> 10738.2 | L30: =テーブル1[[#This Row],[RETAIL PRICE(JPY)]]*50% -> 5369.1
C31: =SKUマスタ!$B$7 -> BWFW1_003 | D31: =テーブル1[[#This Row],[STYLE NUMBER]]&"-"& _xlfn.XLOOKUP(G31, カラーコード!$C$2:$C$50, カラーコード!$D$2:$D$50,"未登録") &"-"&テーブル1[[#This Row],[SIZE]] -> BWFW1_003-BK-L | E31: =SKUマスタ!$C$7 -> P/O Parka | F31: =SKUマスタ!$D$7 -> TOPS | G31: BLACK | H31: L | I31: =SKUマスタ!$J$7 -> D1 | J31: 1 | K31: =SKUマスタ!$G$7*110% -> 10738.2 | L31: =テーブル1[[#This Row],[RETAIL PRICE(JPY)]]*50% -> 5369.1
C32: =SKUマスタ!$B$7 -> BWFW1_003 | D32: =テーブル1[[#This Row],[STYLE NUMBER]]&"-"& _xlfn.XLOOKUP(G32, カラーコード!$C$2:$C$50, カラーコード!$D$2:$D$50,"未登録") &"-"&テーブル1[[#This Row],[SIZE]] -> BWFW1_003-YG-S | E32: =SKUマスタ!$C$7 -> P/O Parka | F32: =SKUマスタ!$D$7 -> TOPS | G32: YellowGreen | H32: S | I32: =SKUマスタ!$J$7 -> D1 | J32: 1 | K32: =SKUマスタ!$G$7*110% -> 10738.2 | L32: =テーブル1[[#This Row],[RETAIL PRICE(JPY)]]*50% -> 5369.1
C33: =SKUマスタ!$B$7 -> BWFW1_003 | D33: =テーブル1[[#This Row],[STYLE NUMBER]]&"-"& _xlfn.XLOOKUP(G33, カラーコード!$C$2:$C$50, カラーコード!$D$2:$D$50,"未登録") &"-"&テーブル1[[#This Row],[SIZE]] -> BWFW1_003-YG-M | E33: =SKUマスタ!$C$7 -> P/O Parka | F33: =SKUマスタ!$D$7 -> TOPS | G33: YellowGreen | H33: M | I33: =SKUマスタ!$J$7 -> D1 | J33: 1 | K33: =SKUマスタ!$G$7*110% -> 10738.2 | L33: =テーブル1[[#This Row],[RETAIL PRICE(JPY)]]*50% -> 5369.1
C34: =SKUマスタ!$B$7 -> BWFW1_003 | D34: =テーブル1[[#This Row],[STYLE NUMBER]]&"-"& _xlfn.XLOOKUP(G34, カラーコード!$C$2:$C$50, カラーコード!$D$2:$D$50,"未登録") &"-"&テーブル1[[#This Row],[SIZE]] -> BWFW1_003-YG-L | E34: =SKUマスタ!$C$7 -> P/O Parka | F34: =SKUマスタ!$D$7 -> TOPS | G34: YellowGreen | H34: L | I34: =SKUマスタ!$J$7 -> D1 | J34: 1 | K34: =SKUマスタ!$G$7*110% -> 10738.2 | L34: =テーブル1[[#This Row],[RETAIL PRICE(JPY)]]*50% -> 5369.1
C35: =SKUマスタ!#REF! -> #REF! | D35: =テーブル1[[#This Row],[STYLE NUMBER]]&"-"& _xlfn.XLOOKUP(G35, カラーコード!$C$2:$C$50, カラーコード!$D$2:$D$50,"未登録") &"-"&テーブル1[[#This Row],[SIZE]] -> #REF! | E35: =SKUマスタ!#REF! -> #REF! | F35: =SKUマスタ!#REF! -> #REF! | G35: BLACK | H35: S | I35: =SKUマスタ!#REF! -> #REF! | J35: 1 | K35: =SKUマスタ!#REF!*110% -> #REF! | L35: =テーブル1[[#This Row],[RETAIL PRICE(JPY)]]*50% -> #REF!
C36: =SKUマスタ!#REF! -> #REF! | D36: =テーブル1[[#This Row],[STYLE NUMBER]]&"-"& _xlfn.XLOOKUP(G36, カラーコード!$C$2:$C$50, カラーコード!$D$2:$D$50,"未登録") &"-"&テーブル1[[#This Row],[SIZE]] -> #REF! | E36: =SKUマスタ!#REF! -> #REF! | F36: =SKUマスタ!#REF! -> #REF! | G36: BLACK | H36: M | I36: =SKUマスタ!#REF! -> #REF! | J36: 1 | K36: =SKUマスタ!#REF!*110% -> #REF! | L36: =テーブル1[[#This Row],[RETAIL PRICE(JPY)]]*50% -> #REF!
C37: =SKUマスタ!#REF! -> #REF! | D37: =テーブル1[[#This Row],[STYLE NUMBER]]&"-"& _xlfn.XLOOKUP(G37, カラーコード!$C$2:$C$50, カラーコード!$D$2:$D$50,"未登録") &"-"&テーブル1[[#This Row],[SIZE]] -> #REF! | E37: =SKUマスタ!#REF! -> #REF! | F37: =SKUマスタ!#REF! -> #REF! | G37: BLACK | H37: L | I37: =SKUマスタ!#REF! -> #REF! | J37: 1 | K37: =SKUマスタ!#REF!*110% -> #REF! | L37: =テーブル1[[#This Row],[RETAIL PRICE(JPY)]]*50% -> #REF!
C38: =SKUマスタ!#REF! -> #REF! | D38: =テーブル1[[#This Row],[STYLE NUMBER]]&"-"& _xlfn.XLOOKUP(G38, カラーコード!$C$2:$C$50, カラーコード!$D$2:$D$50,"未登録") &"-"&テーブル1[[#This Row],[SIZE]] -> #REF! | E38: =SKUマスタ!#REF! -> #REF! | F38: =SKUマスタ!#REF! -> #REF! | G38: YellowGreen | H38: S | I38: =SKUマスタ!#REF! -> #REF! | J38: 1 | K38: =SKUマスタ!#REF!*110% -> #REF! | L38: =テーブル1[[#This Row],[RETAIL PRICE(JPY)]]*50% -> #REF!
C39: =SKUマスタ!#REF! -> #REF! | D39: =テーブル1[[#This Row],[STYLE NUMBER]]&"-"& _xlfn.XLOOKUP(G39, カラーコード!$C$2:$C$50, カラーコード!$D$2:$D$50,"未登録") &"-"&テーブル1[[#This Row],[SIZE]] -> #REF! | E39: =SKUマスタ!#REF! -> #REF! | F39: =SKUマスタ!#REF! -> #REF! | G39: YellowGreen | H39: M | I39: =SKUマスタ!#REF! -> #REF! | J39: 1 | K39: =SKUマスタ!#REF!*110% -> #REF! | L39: =テーブル1[[#This Row],[RETAIL PRICE(JPY)]]*50% -> #REF!
C40: =SKUマスタ!#REF! -> #REF! | D40: =テーブル1[[#This Row],[STYLE NUMBER]]&"-"& _xlfn.XLOOKUP(G40, カラーコード!$C$2:$C$50, カラーコード!$D$2:$D$50,"未登録") &"-"&テーブル1[[#This Row],[SIZE]] -> #REF! | E40: =SKUマスタ!#REF! -> #REF! | F40: =SKUマスタ!#REF! -> #REF! | G40: YellowGreen | H40: L | I40: =SKUマスタ!#REF! -> #REF! | J40: 1 | K40: =SKUマスタ!#REF!*110% -> #REF! | L40: =テーブル1[[#This Row],[RETAIL PRICE(JPY)]]*50% -> #REF!
C41: =SKUマスタ!#REF! -> #REF! | D41: =テーブル1[[#This Row],[STYLE NUMBER]]&"-"& _xlfn.XLOOKUP(G41, カラーコード!$C$2:$C$50, カラーコード!$D$2:$D$50,"未登録") &"-"&テーブル1[[#This Row],[SIZE]] -> #REF! | E41: =SKUマスタ!#REF! -> #REF! | F41: =SKUマスタ!#REF! -> #REF! | G41: YellowGreen | H41: F | I41: =SKUマスタ!#REF! -> #REF! | J41: 1 | K41: =SKUマスタ!#REF!*110% -> #REF! | L41: =テーブル1[[#This Row],[RETAIL PRICE(JPY)]]*50% -> #REF!
...

Sheet カテゴリ別構成
B2: カテゴリ | C2: 予定アイテム数 | D2: 実際アイテム数 | E2: 目標比率 | F2: 実績比率
B3: TOPS | C3: 40 | D3: 38 | E3: 50% | F3: 47.5%
B4: BOTTOMS | C4: 25 | D4: 26 | E4: 31.25% | F4: 32.5%
B5: OUTER | C5: 15 | D5: 16 | E5: 18.75% | F5: 20%
B6: ACC | C6: 15 | D6: 16 | E6: 18.75% | F6: 20%

Sheet お見積もり
B1: コスト計算
B2: スタイルナンバー | C2: アイテム | D2: ボディ品番 | E2: カラー | F2: サイズ | G2: 価格 | H2: ネーム代 | I2: 二次加工代 | J2: アプリケーション代 | K2: コスト | L2: 原価率 | M2: 上代（税抜） | O2: プリント代（小） | P2: プリント（大）
B3: BWSS01_001 | C3: Tシャツ | D3: 5001ー05 | E3: ホワイト | F3: S~XL | G3: 498 | H3: 380 | I3: =$R$16 -> 1335 | J3: =$T$13 -> 511 | K3: =SUM(G3:J3) -> 2724 | L3: 0.42 | M3: =ROUNDUP(K3/L3,-2) -> 6500 | O3: 500 | P3: 800
B4: BWSS01_001 | C4: Tシャツ | D4: 5001ー05 | E4: カラー（ブラック） | F4: S~XL | G4: 535 | H4: 380 | I4: =$R$16 -> 1335 | J4: =$T$13 -> 511 | K4: =SUM(G4:J4) -> 2761 | L4: 0.42 | M4: =ROUNDUP(K4/L4,-2) -> 6600
B5: BWSS01_001 | C5: Tシャツ | D5: 5001ー05 | E5: ホワイト | F5: XXL | G5: 620 | H5: 380 | I5: =$R$16 -> 1335 | J5: =$T$13 -> 511 | K5: =SUM(G5:J5) -> 2846 | L5: 0.42 | M5: =ROUNDUP(K5/L5,-2) -> 6800 | O5: 二次加工名 | P5: 版代 | Q5: 枚数 | R5: コスト
B6: BWSS01_001 | C6: Tシャツ | D6: 5001ー05 | E6: カラー（ブラック） | F6: XXL | G6: 705 | H6: 380 | I6: =$R$16 -> 1335 | J6: =$T$13 -> 511 | K6: =SUM(G6:J6) -> 2931 | L6: 0.42 | M6: =ROUNDUP(K6/L6,-2) -> 7000 | O6: ワンポイント刺繍ロゴ | P6: 9000 | Q6: 600 | R6: =ROUNDUP(P6/Q6,0) -> 15
B7: BWSS01_002 | C7: Tシャツ | D7: 5001ー05 | E7: ホワイト | F7: S~XL | G7: 498 | H7: 380 | I7: =$R$17 -> 1335 | J7: =$T$13 -> 511 | K7: =SUM(G7:J7) -> 2724 | L7: 0.42 | M7: =ROUNDUP(K7/L7,-2) -> 6500 | O7: BWプリント | P7: 12000 | Q7: 600 | R7: =ROUNDUP(P7/Q7,0) -> 20
B8: BWSS01_002 | C8: Tシャツ | D8: 5001ー05 | E8: カラー（ブラック） | F8: S~XL | G8: 535 | H8: 380 | I8: =$R$17 -> 1335 | J8: =$T$13 -> 511 | K8: =SUM(G8:J8) -> 2761 | L8: 0.42 | M8: =ROUNDUP(K8/L8,-2) -> 6600
B9: BWSS01_002 | C9: Tシャツ | D9: 5001ー05 | E9: ホワイト | F9: XXL | G9: 620 | H9: 380 | I9: =$R$17 -> 1335 | J9: =$T$13 -> 511 | K9: =SUM(G9:J9) -> 2846 | L9: 0.42 | M9: =ROUNDUP(K9/L9,-2) -> 6800 | O9: アプリケーション名 | P9: 版代 | Q9: 枚数 | R9: 版代単価 | S9: 単価 | T9: コスト
B10: BWSS01_002 | C10: Tシャツ | D10: 5001ー05 | E10: カラー（ブラック） | F10: XXL | G10: 705 | H10: 380 | I10: =$R$17 -> 1335 | J10: =$T$13 -> 511 | K10: =SUM(G10:J10) -> 2931 | L10: 0.42 | M10: =ROUNDUP(K10/L10,-2) -> 7000 | O10: 下げ札 | P10: 61500 | Q10: 600 | R10: =ROUNDUP(P10/Q10,0) -> 103 | S10: 240 | T10: =R10+S10 -> 343
B11: BWFW01_003 | C11: パーカ | D11: 561801 | F11: S~XL | G11: 1980 | H11: 380 | I11: =$R$17 -> 1335 | J11: =$T$13 -> 511 | K11: =SUM(G11:J11) -> 4206 | L11: 0.42 | M11: =ROUNDUP(K11/L11,-2) -> 10100 | O11: ブランドネーム | P11: 23000 | Q11: 600 | R11: =ROUNDUP(P11/Q11,0) -> 39 | S11: 45 | T11: =R11+S11 -> 84
O12: ブランドタグ | P12: 23000 | Q12: 600 | R12: =ROUNDUP(P12/Q12,0) -> 39 | S12: 45 | T12: =R12+S12 -> 84
S13: 小計 | T13: =SUM(T10:T12) -> 511
B14: BWSS01_001 | C14: Tシャツ | D14: 1100ー01 | E14: ホワイト | F14: S~XL | G14: 728 | H14: 380 | I14: =$R$16 -> 1335 | J14: =$T$13 -> 511 | K14: =SUM(G14:J14) -> 2954 | L14: 0.42 | M14: =ROUNDUP(K14/L14,-2) -> 7100
B15: BWSS01_001 | C15: Tシャツ | D15: 1100ー01 | E15: カラー（ブラック） | F15: S~XL | G15: 775 | H15: 380 | I15: =$R$16 -> 1335 | J15: =$T$13 -> 511 | K15: =SUM(G15:J15) -> 3001 | L15: 0.42 | M15: =ROUNDUP(K15/L15,-2) -> 7200 | O15: スタイルナンバー | P15: 二次加工代 | Q15: プリント代 | R15: 小計
B16: BWSS01_001 | C16: Tシャツ | D16: 1100ー01 | E16: ホワイト | F16: XXL | G16: 925 | O16: BWSS01_001 | P16: =R6+R7 -> 35 | Q16: =$O$3+$P$3 -> 1300 | R16: =SUM(P16:Q16) -> 1335
B17: BWSS01_001 | C17: Tシャツ | D17: 1100ー01 | E17: カラー（ブラック） | F17: XXL | G17: 1018 | O17: BWSS01_002 | P17: =$R$6+$R$7 -> 35 | Q17: =$O$3+$P$3 -> 1300 | R17: =SUM(P17:Q17) -> 1335
B18: BWSS01_002 | C18: Tシャツ | D18: 1100ー01 | E18: ホワイト | F18: S~XL | G18: 728 | H18: 380 | I18: =$R$17 -> 1335 | J18: =$T$13 -> 511 | K18: =SUM(G18:J18) -> 2954 | L18: 0.42 | M18: =ROUNDUP(K18/L18,-2) -> 7100 | O18: BWFW01_003 | P18: =$R$6+$R$7 -> 35 | Q18: =$O$3+$P$3 -> 1300 | R18: =SUM(P18:Q18) -> 1335
B19: BWSS01_002 | C19: Tシャツ | D19: 1100ー01 | E19: カラー（ブラック） | F19: S~XL | G19: 775 | H19: 380 | I19: =$R$17 -> 1335 | J19: =$T$13 -> 511 | K19: =SUM(G19:J19) -> 3001 | L19: 0.42 | M19: =ROUNDUP(K19/L19,-2) -> 7200
B20: BWSS01_002 | C20: Tシャツ | D20: 1100ー01 | E20: ホワイト | F20: XXL | G20: 925
B21: BWSS01_002 | C21: Tシャツ | D21: 1100ー01 | E21: カラー（ブラック） | F21: XXL | G21: 1018

Sheet カラーコード
B2: 行 | C2: 名称 | D2: code | E2: Pantone | F2: パントーン名称 | G2: カラーナンバー | H2: カラー展開（ＮＯ．） | I2: 刺繍糸パールヨット | J2: ファスナーテープ | K2: パイピング新道（P-002） | L2: Name
B3: 1 | C3: WHITE | D3: WH | E3: 00-0000TPX | F3: white | G3: 000 | L3: =$G3&"："&$C3 -> 000：WHITE
B4: 2 | C4: BLACK | D4: BK | E4: 00-0000TPX | F4: black | G4: 001 | L4: =$G4&"："&$C4 -> 001：BLACK
B5: 3 | C5: ネイビーブルー | D5: NV | E5: 19-3920TCX | F5: Peacoat | G5: 002 | L5: =$G5&"："&$C5 -> 002：ネイビーブルー
B6: 4 | C6: サンセットレッド | D6: RD | E6: 18-1662TCX | F6: Flame Scarlet | G6: 003 | L6: =$G6&"："&$C6 -> 003：サンセットレッド
B7: 5 | C7: アイスグレー | D7: IG | E7: 14-4102TCX | F7: Glacier Gray | G7: 004 | L7: =$G7&"："&$C7 -> 004：アイスグレー
B8: 6 | C8: ブラストブルー | E8: 19-4053TCX | F8: Turkish Sea | G8: 005 | L8: =$G8&"："&$C8 -> 005：ブラストブルー
B9: 7 | C9: ディープシー | E9: 18-4525TCX | F9: Caribbean Sea | G9: 006 | L9: =$G9&"："&$C9 -> 006：ディープシー
B10: 8 | C10: バイオレット | E10: 18-3943TCX | F10: Blue Iris | G10: 007 | L10: =$G10&"："&$C10 -> 007：バイオレット
B11: 9 | C11: スモークミント | E11: 16-4408TCX | F11: Slate | G11: 008 | L11: =$G11&"："&$C11 -> 008：スモークミント
B12: 10 | C12: クリアーレッド | E12: 17-1663TCX | F12: Bittersweet | G12: 009 | L12: =$G12&"："&$C12 -> 009：クリアーレッド
B13: 11 | C13: シトラスオレンジ | E13: 14-0955TCX | F13: Citrus | G13: 010 | L13: =$G13&"："&$C13 -> 010：シトラスオレンジ
B14: 12 | C14: オレンジブラウン | E14: 18-1536TCX | F14: Hot Sauce | G14: 011 | L14: =$G14&"："&$C14 -> 011：オレンジブラウン
B15: 13 | C15: パステルグリーン | E15: 12-0225TCX | F15: Patina Green | G15: 012 | L15: =$G15&"："&$C15 -> 012：パステルグリーン
B16: 14 | C16: パステルピンク | E16: 15-2214TCX | F16: Rosebloom | G16: 013 | L16: =$G16&"："&$C16 -> 013：パステルピンク
B17: 15 | C17: チョコレート | E17: 19-3903TCX | F17: Shale | G17: 014 | L17: =$G17&"："&$C17 -> 014：チョコレート
B18: 16 | C18: サファイヤネイビー | E18: 19-3943TCX | F18: Bellwether Blue | G18: 015 | L18: =$G18&"："&$C18 -> 015：サファイヤネイビー
B19: 17 | C19: ダークネイビー | E19: 19-4111TCX | F19: Pageant Blue | G19: 016 | L19: =$G19&"："&$C19 -> 016：ダークネイビー
... B33: 31 | C33: コッパー | E33: 16-1325TCX | F33: Copper | G33: 030 | L33: =$G33&"："&$C33 -> 030：コッパー
B34: 32 | C34: YellowGreen | D34: YG | G34: 031
B35: 33 | G35: 032
B36: 34 | G36: 033
B37: 35 | G37: 034
B38: 36 | G38: 035
B39: 37 | G39: 036
B40: 38 | G40: 037
B41: 39 | G41: 038
B42: 40 | G42: 039

Sheet デリバリーリスト
B2: シーズン | C2: デリバリー区分 | D2: 目安時期 | E2: アイテム例
B3: SS | C3: D1 | D3: 2月下旬〜3月上旬 | E3: 春物立ち上がり（薄手アウター、長袖）
B4: SS | C4: D2 | D4: 3月中旬 | E4: 中間アイテム（カットソー、軽トップス）
B5: SS | C5: D3 | D5: 4月上旬 | E5: 初夏向け（半袖、スカート）
B6: SS | C6: D4 | D6: 4月下旬〜5月上旬 | E6: 夏本番アイテム（タンクトップ、ショーツ）
B7: FW | C7: D1 | D7: 8月上旬 | E7: 秋物立ち上がり（ライトアウター）
B8: FW | C8: D2 | D8: 8月下旬〜9月上旬 | E8: 中厚手トップス、パンツ
B9: FW | C9: D3 | D9: 9月中旬 | E9: 本格秋アイテム（ニット、厚手シャツ）
B10: FW | C10: D4 | D10: 10月上旬 | E10: アウター、防寒アイテム本番

Sheet Marketing

Sheet reference
